Workbook

Sheet README
A1: Capital Planning & Stress Projection Model (MDL-CAP-003)
A2: Meridian Harbor Financial Corp. - model documentation sheet
A3: SYNTHETIC DOCUMENT FOR A PROOF OF CONCEPT. Meridian Harbor Financial Corp. is a fictional institution. All names, figures and events are invented and do not describe any real company.
A5: Model ID | B5: MDL-CAP-003
A6: Model name | B6: Capital Planning & Stress Projection Model
A7: Risk tier | B7: Tier 1 (High)
A8: Model owner | B8: Corporate Treasury - Capital Management
A9: Independent validator | B9: Model Risk Governance & Review (MRGR)
A10: Last validation | B10: 2026-02-27
A11: Next validation due | B11: 2027-02-28
A12: Purpose | B12: Projects CET1 capital, RWA and capital ratios over a nine-quarter horizon under baseline and severely adverse scenarios to size distributions.
A13: Upstream data feeds (APIs) | B13: API-16 Regulatory Reporting API; API-14 Macroeconomic Scenario API; API-15 Treasury Liquidity Positions API
A14: Downstream disclosures | B14: Annual Report - Capital Risk Management; Pillar 3 - Capital Planning and Stress Testing
A15: Units | B15: USD millions unless stated otherwise; rates stored as decimals
A16: As-of date | B16: See Assumptions sheet
A18: Sheets
A19: Assumptions | B19: Starting capital position (Q2 2026), distribution plan, growth and requirement stack.
A20: Baseline_Projection | B20: Nine-quarter CET1 projection under the firm's baseline plan.
A21: Stress_Projection | B21: Nine-quarter projection under the severely adverse scenario.
A22: Summary | B22: Minimum ratios, capital headroom and an indicative stress capital buffer (SCB).
A24: How the model works
A25: 1. | B25: CET1(t) = CET1(t-1) + net income - preferred dividends - common dividends - share repurchases + other CET1 movements.
A26: 2. | B26: Common dividends = shares outstanding x dividend per share; shares fall by buyback dollars / assumed share price.
A27: 3. | B27: RWA(t) = RWA(t-1) x (1 + quarterly growth).
A28: 4. | B28: Stress: pre-tax income = PPNR - provisions - trading & counterparty losses; tax at the effective rate (tax benefit recognised on losses); buybacks suspended; dividends held flat.
A29: 5. | B29: Indicative SCB = start CET1 ratio - minimum stressed CET1 ratio + four quarters of planned dividends / starting RWA, floored at 2.5%.
A31: Key inputs
A32: 1. | B32: Starting CET1 capital and RWA from API-16 Regulatory Reporting API (FR Y-9C / FFIEC 101 extract).
A33: 2. | B33: Scenario paths from API-14 Macroeconomic Scenario API (severely adverse, CCAR 2026 analogue).
A34: 3. | B34: Liquidity constraints on distributions cross-checked against API-15 Treasury Liquidity Positions API.
A35: 4. | B35: Distribution plan (dividends, buybacks) approved by the Board Capital Committee.
A37: Key outputs
A38: 1. | B38: Quarter-end CET1 ratio path versus management target and regulatory requirement.
A39: 2. | B39: Minimum stressed CET1 ratio and indicative SCB.
A40: 3. | B40: Capacity for additional buybacks at the management target.
A42: Limits, controls and known limitations
A43: 1. | B43: Management target CET1 ratio: 13.0%; regulatory requirement = 4.5% + SCB + G-SIB surcharge.
A44: 2. | B44: Simplified: no AOCI volatility modelling, no deferred-tax-asset threshold deductions.
A45: 3. | B45: Stress losses are top-down inputs supplied by the enterprise stress testing program.
A47: Colour legend
...

Sheet Summary
A1: Capital Planning Summary
A2: Feeds Annual Report (Capital Risk Management) and Pillar 3 (stress testing)
A3: SYNTHETIC DOCUMENT FOR A PROOF OF CONCEPT. Meridian Harbor Financial Corp. is a fictional institution. All names, figures and events are invented and do not describe any real company.
A5: Metric | B5: Value | C5: Note
A6: Starting CET1 ratio (Q2 2026) | B6: =Baseline_Projection!B15 -> 0.15140634
A7: Ending CET1 ratio - baseline (Q3 2028) | B7: =Baseline_Projection!K15 -> 0.16145595
A8: Minimum CET1 ratio - baseline | B8: =MIN(Baseline_Projection!C15:K15) -> 0.15228009
A9: Minimum CET1 ratio - severely adverse | B9: =MIN(Stress_Projection!C20:K20) -> 0.12898397
A10: Peak-to-trough CET1 decline (stress) | B10: =B6-B9 -> 0.022422372 | C10: Starting ratio minus minimum stressed ratio
A11: Four quarters of planned dividends / starting RWA | B11: =-SUM(Baseline_Projection!C9:F9)/Baseline_Projection!B14 -> 0.009385985 | C11: Dividend add-on in SCB formula
A12: Indicative stress capital buffer (SCB) | B12: =MAX(0.025,B10+B11) -> 0.031808357 | C12: Floored at 2.5%
A13: Regulatory CET1 requirement (current SCB) | B13: =Assumptions!$B$23 -> 0.102 | C13: 4.5% + SCB + G-SIB surcharge
A14: Regulatory CET1 requirement (indicative SCB) | B14: =Assumptions!$B$18+B12+Assumptions!$B$20 -> 0.10180836
A15: Management target | B15: =Assumptions!$B$21 -> 0.13
A16: Cumulative buybacks over horizon ($mm) | B16: =-SUM(Baseline_Projection!C10:K10) -> 27000
A17: Excess CET1 vs target at Q3 2028 ($mm) | B17: =Baseline_Projection!K17 -> 22994.906 | C17: Additional distribution capacity at the target
A18: Stress minimum above requirement? | B18: =IF(B9>=B13,"YES","NO - capital action required") -> YES

Sheet Assumptions
A1: Assumptions
A2: Starting point: Q2 2026 actuals
A3: SYNTHETIC DOCUMENT FOR A PROOF OF CONCEPT. Meridian Harbor Financial Corp. is a fictional institution. All names, figures and events are invented and do not describe any real company.
A5: Assumption | B5: Value | C5: Source / note
A6: Starting CET1 capital ($mm) | B6: 101200 | C6: API-16, Q2 2026 regulatory capital
A7: Starting standardized RWA ($mm) | B7: 668400 | C7: API-16, Q2 2026
A8: Starting common shares outstanding (mm) | B8: 1381 | C8: Transfer agent, 2026-06-30
A9: Baseline quarterly net income ($mm) | B9: 6600 | C9: Financial plan 2026-2028
A10: Net income growth per quarter | B10: 0.008 | C10: Financial plan
A11: Preferred dividends per quarter ($mm) | B11: 260 | C11: Contractual
A12: Common dividend per share per quarter ($) | B12: 1.15 | C12: Board-declared; flat in projection
A13: Share repurchases per quarter ($mm) | B13: 3000 | C13: Board-authorised program ($30bn, 2025-2028)
A14: Assumed share price ($) | B14: 262 | C14: Flat assumption for share count roll-forward
A15: Baseline RWA growth per quarter | B15: 0.01 | C15: Balance sheet plan
A16: Other CET1 movements per quarter ($mm) | B16: -150 | C16: AOCI, deductions, employee stock plans (net)
A17: Effective tax rate | B17: 0.22 | C17: FY2025 effective rate
... A21: Management target CET1 ratio | B21: 0.13 | C21: Board Capital Committee
A23: Regulatory CET1 requirement | B23: =B18+B19+B20 -> 0.102

Sheet Baseline_Projection
A1: Baseline Projection
A2: Quarterly, $mm
A3: SYNTHETIC DOCUMENT FOR A PROOF OF CONCEPT. Meridian Harbor Financial Corp. is a fictional institution. All names, figures and events are invented and do not describe any real company.
A5: Line item | B5: Q2 2026 (actual) | C5: Q3 2026 | D5: Q4 2026 | E5: Q1 2027 | F5: Q2 2027 | G5: Q3 2027 | H5: Q4 2027 | I5: Q1 2028 | J5: Q2 2028 | K5: Q3 2028
A6: Beginning CET1 capital | C6: =B12 -> 101200 | D6: =C12 -> 102801.85 | E6: =D12 -> 104469.67 | F6: =E12 -> 106203.88 | G6: =F12 -> 108004.9 | H6: =G12 -> 109873.17 | I6: =H12 -> 111809.12 | J6: =I12 -> 113813.18 | K6: =J12 -> 115885.79
A7: Net income | C7: =Assumptions!$B$9*(1+Assumptions!$B$10)^0 -> 6600 | D7: =Assumptions!$B$9*(1+Assumptions!$B$10)^1 -> 6652.8 | E7: =Assumptions!$B$9*(1+Assumptions!$B$10)^2 -> 6706.0224 | F7: =Assumptions!$B$9*(1+Assumptions!$B$10)^3 -> 6759.6706 | G7: =Assumptions!$B$9*(1+Assumptions!$B$10)^4 -> 6813.7479 | H7: =Assumptions!$B$9*(1+Assumptions!$B$10)^5 -> 6868.2579 | I7: =Assumptions!$B$9*(1+Assumptions!$B$10)^6 -> 6923.204 | J7: =Assumptions!$B$9*(1+Assumptions!$B$10)^7 -> 6978.5896 | K7: =Assumptions!$B$9*(1+Assumptions!$B$10)^8 -> 7034.4183
A8: Preferred dividends | C8: =-Assumptions!$B$11 -> -260 | D8: =-Assumptions!$B$11 -> -260 | E8: =-Assumptions!$B$11 -> -260 | F8: =-Assumptions!$B$11 -> -260 | G8: =-Assumptions!$B$11 -> -260 | H8: =-Assumptions!$B$11 -> -260 | I8: =-Assumptions!$B$11 -> -260 | J8: =-Assumptions!$B$11 -> -260 | K8: =-Assumptions!$B$11 -> -260
A9: Common dividends | C9: =-B16*Assumptions!$B$12 -> -1588.15 | D9: =-C16*Assumptions!$B$12 -> -1574.9821 | E9: =-D16*Assumptions!$B$12 -> -1561.8141 | F9: =-E16*Assumptions!$B$12 -> -1548.6462 | G9: =-F16*Assumptions!$B$12 -> -1535.4782 | H9: =-G16*Assumptions!$B$12 -> -1522.3103 | I9: =-H16*Assumptions!$B$12 -> -1509.1424 | J9: =-I16*Assumptions!$B$12 -> -1495.9744 | K9: =-J16*Assumptions!$B$12 -> -1482.8065
A10: Share repurchases | C10: =-Assumptions!$B$13 -> -3000 | D10: =-Assumptions!$B$13 -> -3000 | E10: =-Assumptions!$B$13 -> -3000 | F10: =-Assumptions!$B$13 -> -3000 | G10: =-Assumptions!$B$13 -> -3000 | H10: =-Assumptions!$B$13 -> -3000 | I10: =-Assumptions!$B$13 -> -3000 | J10: =-Assumptions!$B$13 -> -3000 | K10: =-Assumptions!$B$13 -> -3000
A11: Other CET1 movements | C11: =Assumptions!$B$16 -> -150 | D11: =Assumptions!$B$16 -> -150 | E11: =Assumptions!$B$16 -> -150 | F11: =Assumptions!$B$16 -> -150 | G11: =Assumptions!$B$16 -> -150 | H11: =Assumptions!$B$16 -> -150 | I11: =Assumptions!$B$16 -> -150 | J11: =Assumptions!$B$16 -> -150 | K11: =Assumptions!$B$16 -> -150
A12: Ending CET1 capital | B12: =Assumptions!$B$6 -> 101200 | C12: =C6+C7+C8+C9+C10+C11 -> 102801.85 | D12: =D6+D7+D8+D9+D10+D11 -> 104469.67 | E12: =E6+E7+E8+E9+E10+E11 -> 106203.88 | F12: =F6+F7+F8+F9+F10+F11 -> 108004.9 | G12: =G6+G7+G8+G9+G10+G11 -> 109873.17 | H12: =H6+H7+H8+H9+H10+H11 -> 111809.12 | I12: =I6+I7+I8+I9+I10+I11 -> 113813.18 | J12: =J6+J7+J8+J9+J10+J11 -> 115885.79 | K12: =K6+K7+K8+K9+K10+K11 -> 118027.41
A13: RWA growth | C13: =Assumptions!$B$15 -> 0.01 | D13: =Assumptions!$B$15 -> 0.01 | E13: =Assumptions!$B$15 -> 0.01 | F13: =Assumptions!$B$15 -> 0.01 | G13: =Assumptions!$B$15 -> 0.01 | H13: =Assumptions!$B$15 -> 0.01 | I13: =Assumptions!$B$15 -> 0.01 | J13: =Assumptions!$B$15 -> 0.01 | K13: =Assumptions!$B$15 -> 0.01
A14: Standardized RWA | B14: =Assumptions!$B$7 -> 668400 | C14: =B14*(1+C13) -> 675084 | D14: =C14*(1+D13) -> 681834.84 | E14: =D14*(1+E13) -> 688653.19 | F14: =E14*(1+F13) -> 695539.72 | G14: =F14*(1+G13) -> 702495.12 | H14: =G14*(1+H13) -> 709520.07 | I14: =H14*(1+I13) -> 716615.27 | J14: =I14*(1+J13) -> 723781.42 | K14: =J14*(1+K13) -> 731019.24
A15: CET1 ratio | B15: =B12/B14 -> 0.15140634 | C15: =IF(C14=0,0,C12/C14) -> 0.15228009 | D15: =IF(D14=0,0,D12/D14) -> 0.15321844 | E15: =IF(E14=0,0,E12/E14) -> 0.15421968 | F15: =IF(F14=0,0,F12/F14) -> 0.15528215 | G15: =IF(G14=0,0,G12/G14) -> 0.15640418 | H15: =IF(H14=0,0,H12/H14) -> 0.15758415 | I15: =IF(I14=0,0,I12/I14) -> 0.15882048 | J15: =IF(J14=0,0,J12/J14) -> 0.16011159 | K15: =IF(K14=0,0,K12/K14) -> 0.16145595
A16: Shares outstanding (mm) | B16: =Assumptions!$B$8 -> 1381 | C16: =B16+C10/Assumptions!$B$14 -> 1369.5496 | D16: =C16+D10/Assumptions!$B$14 -> 1358.0992 | E16: =D16+E10/Assumptions!$B$14 -> 1346.6489 | F16: =E16+F10/Assumptions!$B$14 -> 1335.1985 | G16: =F16+G10/Assumptions!$B$14 -> 1323.7481 | H16: =G16+H10/Assumptions!$B$14 -> 1312.2977 | I16: =H16+I10/Assumptions!$B$14 -> 1300.8473 | J16: =I16+J10/Assumptions!$B$14 -> 1289.3969 | K16: =J16+K10/Assumptions!$B$14 -> 1277.9466
A17: Headroom vs management target ($mm) | C17: =C12-Assumptions!$B$21*C14 -> 15040.93 | D17: =D12-Assumptions!$B$21*D14 -> 15831.139 | E17: =E12-Assumptions!$B$21*E14 -> 16678.962 | F17: =F12-Assumptions!$B$21*F14 -> 17584.737 | G17: =G12-Assumptions!$B$21*G14 -> 18548.805 | H17: =H12-Assumptions!$B$21*H14 -> 19571.509 | I17: =I12-Assumptions!$B$21*I14 -> 20653.195 | J17: =J12-Assumptions!$B$21*J14 -> 21794.21 | K17: =K12-Assumptions!$B$21*K14 -> 22994.906
A18: Headroom vs regulatory requirement ($mm) | C18: =C12-Assumptions!$B$23*C14 -> 33943.282 | D18: =D12-Assumptions!$B$23*D14 -> 34922.514 | E18: =E12-Assumptions!$B$23*E14 -> 35961.251 | F18: =F12-Assumptions!$B$23*F14 -> 37059.849 | G18: =G12-Assumptions!$B$23*G14 -> 38218.668 | H18: =H12-Assumptions!$B$23*H14 -> 39438.071 | I18: =I12-Assumptions!$B$23*I14 -> 40718.422 | J18: =J12-Assumptions!$B$23*J14 -> 42060.09 | K18: =K12-Assumptions!$B$23*K14 -> 43463.445

Sheet Stress_Projection
A1: Severely Adverse Projection
A2: Quarterly, $mm - stress losses from enterprise stress testing program
A3: SYNTHETIC DOCUMENT FOR A PROOF OF CONCEPT. Meridian Harbor Financial Corp. is a fictional institution. All names, figures and events are invented and do not describe any real company.
A5: Line item | B5: Q2 2026 (actual) | C5: Q3 2026 | D5: Q4 2026 | E5: Q1 2027 | F5: Q2 2027 | G5: Q3 2027 | H5: Q4 2027 | I5: Q1 2028 | J5: Q2 2028 | K5: Q3 2028
A6: Beginning CET1 capital | C6: =B17 -> 101200 | D6: =C17 -> 95067.85 | E6: =D17 -> 93303.7 | F6: =E17 -> 91851.55 | G6: =F17 -> 90867.4 | H6: =G17 -> 90507.25 | I6: =H17 -> 90771.1 | J6: =I17 -> 91580.95 | K6: =J17 -> 92780.8
A7: Pre-provision net revenue (PPNR) | C7: 7400 | D7: 7100 | E7: 6800 | F7: 6600 | G7: 6500 | H7: 6600 | I7: 6800 | J7: 7000 | K7: 7200
A8: Provision for credit losses | C8: -7300 | D8: -6800 | E8: -6100 | F8: -5300 | G8: -4400 | H8: -3700 | I8: -3200 | J8: -2900 | K8: -2700
A9: Trading & counterparty losses | C9: -5400 | D9: 0 | E9: 0 | F9: 0 | G9: 0 | H9: 0 | I9: 0 | J9: 0 | K9: 0
A10: Pre-tax income | C10: =SUM(C7:C9) -> -5300 | D10: =SUM(D7:D9) -> 300 | E10: =SUM(E7:E9) -> 700 | F10: =SUM(F7:F9) -> 1300 | G10: =SUM(G7:G9) -> 2100 | H10: =SUM(H7:H9) -> 2900 | I10: =SUM(I7:I9) -> 3600 | J10: =SUM(J7:J9) -> 4100 | K10: =SUM(K7:K9) -> 4500
A11: Income tax (benefit) | C11: =-C10*Assumptions!$B$17 -> 1166 | D11: =-D10*Assumptions!$B$17 -> -66 | E11: =-E10*Assumptions!$B$17 -> -154 | F11: =-F10*Assumptions!$B$17 -> -286 | G11: =-G10*Assumptions!$B$17 -> -462 | H11: =-H10*Assumptions!$B$17 -> -638 | I11: =-I10*Assumptions!$B$17 -> -792 | J11: =-J10*Assumptions!$B$17 -> -902 | K11: =-K10*Assumptions!$B$17 -> -990
A12: Net income | C12: =C10+C11 -> -4134 | D12: =D10+D11 -> 234 | E12: =E10+E11 -> 546 | F12: =F10+F11 -> 1014 | G12: =G10+G11 -> 1638 | H12: =H10+H11 -> 2262 | I12: =I10+I11 -> 2808 | J12: =J10+J11 -> 3198 | K12: =K10+K11 -> 3510
A13: Preferred dividends | C13: =-Assumptions!$B$11 -> -260 | D13: =-Assumptions!$B$11 -> -260 | E13: =-Assumptions!$B$11 -> -260 | F13: =-Assumptions!$B$11 -> -260 | G13: =-Assumptions!$B$11 -> -260 | H13: =-Assumptions!$B$11 -> -260 | I13: =-Assumptions!$B$11 -> -260 | J13: =-Assumptions!$B$11 -> -260 | K13: =-Assumptions!$B$11 -> -260
A14: Common dividends | C14: =-B21*Assumptions!$B$12 -> -1588.15 | D14: =-C21*Assumptions!$B$12 -> -1588.15 | E14: =-D21*Assumptions!$B$12 -> -1588.15 | F14: =-E21*Assumptions!$B$12 -> -1588.15 | G14: =-F21*Assumptions!$B$12 -> -1588.15 | H14: =-G21*Assumptions!$B$12 -> -1588.15 | I14: =-H21*Assumptions!$B$12 -> -1588.15 | J14: =-I21*Assumptions!$B$12 -> -1588.15 | K14: =-J21*Assumptions!$B$12 -> -1588.15
A15: Share repurchases | C15: 0 | D15: 0 | E15: 0 | F15: 0 | G15: 0 | H15: 0 | I15: 0 | J15: 0 | K15: 0
A16: Other CET1 movements | C16: =Assumptions!$B$16 -> -150 | D16: =Assumptions!$B$16 -> -150 | E16: =Assumptions!$B$16 -> -150 | F16: =Assumptions!$B$16 -> -150 | G16: =Assumptions!$B$16 -> -150 | H16: =Assumptions!$B$16 -> -150 | I16: =Assumptions!$B$16 -> -150 | J16: =Assumptions!$B$16 -> -150 | K16: =Assumptions!$B$16 -> -150
A17: Ending CET1 capital | B17: =Assumptions!$B$6 -> 101200 | C17: =C6+C12+C13+C14+C15+C16 -> 95067.85 | D17: =D6+D12+D13+D14+D15+D16 -> 93303.7 | E17: =E6+E12+E13+E14+E15+E16 -> 91851.55 | F17: =F6+F12+F13+F14+F15+F16 -> 90867.4 | G17: =G6+G12+G13+G14+G15+G16 -> 90507.25 | H17: =H6+H12+H13+H14+H15+H16 -> 90771.1 | I17: =I6+I12+I13+I14+I15+I16 -> 91580.95 | J17: =J6+J12+J13+J14+J15+J16 -> 92780.8 | K17: =K6+K12+K13+K14+K15+K16 -> 94292.65
A18: RWA growth | C18: 0.022 | D18: 0.015 | E18: 0.008 | F18: 0.004 | G18: 0 | H18: -0.002 | I18: -0.004 | J18: -0.004 | K18: -0.004
A19: Standardized RWA | B19: =Assumptions!$B$7 -> 668400 | C19: =B19*(1+C18) -> 683104.8 | D19: =C19*(1+D18) -> 693351.37 | E19: =D19*(1+E18) -> 698898.18 | F19: =E19*(1+F18) -> 701693.78 | G19: =F19*(1+G18) -> 701693.78 | H19: =G19*(1+H18) -> 700290.39 | I19: =H19*(1+I18) -> 697489.23 | J19: =I19*(1+J18) -> 694699.27 | K19: =J19*(1+K18) -> 691920.47
A20: CET1 ratio | B20: =B17/B19 -> 0.15140634 | C20: =IF(C19=0,0,C17/C19) -> 0.13917023 | D20: =IF(D19=0,0,D17/D19) -> 0.13456914 | E20: =IF(E19=0,0,E17/E19) -> 0.13142336 | F20: =IF(F19=0,0,F17/F19) -> 0.12949723 | G20: =IF(G19=0,0,G17/G19) -> 0.12898397 | H20: =IF(H19=0,0,H17/H19) -> 0.12961923 | I20: =IF(I19=0,0,I17/I19) -> 0.13130088 | J20: =IF(J19=0,0,J17/J19) -> 0.13355534 | K20: =IF(K19=0,0,K17/K19) -> 0.13627672
A21: Shares outstanding (mm) | B21: =Assumptions!$B$8 -> 1381 | C21: =B21+C15/Assumptions!$B$14 -> 1381 | D21: =C21+D15/Assumptions!$B$14 -> 1381 | E21: =D21+E15/Assumptions!$B$14 -> 1381 | F21: =E21+F15/Assumptions!$B$14 -> 1381 | G21: =F21+G15/Assumptions!$B$14 -> 1381 | H21: =G21+H15/Assumptions!$B$14 -> 1381 | I21: =H21+I15/Assumptions!$B$14 -> 1381 | J21: =I21+J15/Assumptions!$B$14 -> 1381 | K21: =J21+K15/Assumptions!$B$14 -> 1381
A22: Headroom vs management target ($mm) | C22: =C17-Assumptions!$B$21*C19 -> 6264.226 | D22: =D17-Assumptions!$B$21*D19 -> 3168.0216 | E22: =E17-Assumptions!$B$21*E19 -> 994.78621 | F22: =F17-Assumptions!$B$21*F19 -> -352.79084 | G22: =G17-Assumptions!$B$21*G19 -> -712.94084 | H22: =H17-Assumptions!$B$21*H19 -> -266.65046 | I22: =I17-Assumptions!$B$21*I19 -> 907.35054 | J22: =J17-Assumptions!$B$21*J19 -> 2469.8949 | K22: =K17-Assumptions!$B$21*K19 -> 4342.9886
A23: Headroom vs regulatory requirement ($mm) | C23: =C17-Assumptions!$B$23*C19 -> 25391.16 | D23: =D17-Assumptions!$B$23*D19 -> 22581.86 | E23: =E17-Assumptions!$B$23*E19 -> 20563.935 | F23: =F17-Assumptions!$B$23*F19 -> 19294.635 | G23: =G17-Assumptions!$B$23*G19 -> 18934.485 | H23: =H17-Assumptions!$B$23*H19 -> 19341.48 | I23: =I17-Assumptions!$B$23*I19 -> 20437.049 | J23: =J17-Assumptions!$B$23*J19 -> 21921.474 | K23: =K17-Assumptions!$B$23*K19 -> 23716.762
