Workbook

Sheet Allowance_Summary
A1: Allowance for Loan Losses - Summary and Reconciliation
A2: Feeds Annual Report Note 6 and the earnings supplement
A3: SYNTHETIC DOCUMENT FOR A PROOF OF CONCEPT. Meridian Harbor Financial Corp. is a fictional institution. All names, figures and events are invented and do not describe any real company.
A5: Segment | B5: Upside ECL | C5: Baseline ECL | D5: Downside ECL | E5: Weighted (modeled) ($mm) | F5: Qualitative overlay ($mm) | G5: Total allowance ($mm) | H5: Reported allowance ($mm) | I5: Difference | J5: Overlay % of modeled | K5: Allowance / loans | L5: Coverage of NCOs (yrs)
A6: =Segment_Inputs!A6 -> Credit Card | B6: =ECL_Calc!G7 -> 6894.3585 | C6: =ECL_Calc!G17 -> 7641.7887 | D6: =ECL_Calc!G27 -> 10611.388 | E6: =B6*Scenarios!$B$6+C6*Scenarios!$B$7+D6*Scenarios!$B$8 -> 8383.1826 | F6: 256.81741 | G6: =E6+F6 -> 8640 | H6: =Segment_Inputs!K6 -> 8640 | I6: =G6-H6 -> 0 | J6: =IF(E6=0,0,F6/E6) -> 0.030634834 | K6: =IF(Segment_Inputs!C6=0,0,G6/Segment_Inputs!C6) -> 0.062427746 | L6: =IF(Segment_Inputs!J6=0,0,G6/Segment_Inputs!J6) -> 1.8701299
A7: =Segment_Inputs!A7 -> Residential Mortgage | B7: =ECL_Calc!G8 -> 580.9559 | C7: =ECL_Calc!G18 -> 662.26759 | D7: =ECL_Calc!G28 -> 1058.8003 | E7: =B7*Scenarios!$B$6+C7*Scenarios!$B$7+D7*Scenarios!$B$8 -> 764.96508 | F7: 55.034924 | G7: =E7+F7 -> 820 | H7: =Segment_Inputs!K7 -> 820 | I7: =G7-H7 -> 0 | J7: =IF(E7=0,0,F7/E7) -> 0.071944362 | K7: =IF(Segment_Inputs!C7=0,0,G7/Segment_Inputs!C7) -> 0.0037511436 | L7: =IF(Segment_Inputs!J7=0,0,G7/Segment_Inputs!J7) -> 20.5
A8: =Segment_Inputs!A8 -> Auto | B8: =ECL_Calc!G9 -> 627.11382 | C8: =ECL_Calc!G19 -> 675.41354 | D8: =ECL_Calc!G29 -> 868.10119 | E8: =B8*Scenarios!$B$6+C8*Scenarios!$B$7+D8*Scenarios!$B$8 -> 723.55989 | F8: -33.559892 | G8: =E8+F8 -> 690 | H8: =Segment_Inputs!K8 -> 690 | I8: =G8-H8 -> 0 | J8: =IF(E8=0,0,F8/E8) -> -0.046381637 | K8: =IF(Segment_Inputs!C8=0,0,G8/Segment_Inputs!C8) -> 0.010631741 | L8: =IF(Segment_Inputs!J8=0,0,G8/Segment_Inputs!J8) -> 1.6829268
A9: =Segment_Inputs!A9 -> Commercial Real Estate | B9: =ECL_Calc!G10 -> 1653.8196 | C9: =ECL_Calc!G20 -> 1936.2074 | D9: =ECL_Calc!G30 -> 3150.433 | E9: =B9*Scenarios!$B$6+C9*Scenarios!$B$7+D9*Scenarios!$B$8 -> 2243.9975 | F9: 226.00247 | G9: =E9+F9 -> 2470 | H9: =Segment_Inputs!K9 -> 2470 | I9: =G9-H9 -> 0 | J9: =IF(E9=0,0,F9/E9) -> 0.10071422 | K9: =IF(Segment_Inputs!C9=0,0,G9/Segment_Inputs!C9) -> 0.025152749 | L9: =IF(Segment_Inputs!J9=0,0,G9/Segment_Inputs!J9) -> 6.5
A10: =Segment_Inputs!A10 -> Commercial & Industrial | B10: =ECL_Calc!G11 -> 2222.307 | C10: =ECL_Calc!G21 -> 2416.2582 | D10: =ECL_Calc!G31 -> 3188.9562 | E10: =B10*Scenarios!$B$6+C10*Scenarios!$B$7+D10*Scenarios!$B$8 -> 2609.2773 | F10: 150.72267 | G10: =E10+F10 -> 2760 | H10: =Segment_Inputs!K10 -> 2760 | I10: =G10-H10 -> 0 | J10: =IF(E10=0,0,F10/E10) -> 0.057764143 | K10: =IF(Segment_Inputs!C10=0,0,G10/Segment_Inputs!C10) -> 0.016 | L10: =IF(Segment_Inputs!J10=0,0,G10/Segment_Inputs!J10) -> 4.9285714
A11: =Segment_Inputs!A11 -> Other Consumer & Wholesale | B11: =ECL_Calc!G12 -> 456.20746 | C11: =ECL_Calc!G22 -> 485.10861 | D11: =ECL_Calc!G32 -> 600.45106 | E11: =B11*Scenarios!$B$6+C11*Scenarios!$B$7+D11*Scenarios!$B$8 -> 513.93112 | F11: 26.068882 | G11: =E11+F11 -> 540 | H11: =Segment_Inputs!K11 -> 540 | I11: =G11-H11 -> 0 | J11: =IF(E11=0,0,F11/E11) -> 0.050724466 | K11: =IF(Segment_Inputs!C11=0,0,G11/Segment_Inputs!C11) -> 0.010865191 | L11: =IF(Segment_Inputs!J11=0,0,G11/Segment_Inputs!J11) -> 6
A12: Total | B12: =SUM(B6:B11) -> 12434.762 | C12: =SUM(C6:C11) -> 13817.044 | D12: =SUM(D6:D11) -> 19478.13 | E12: =SUM(E6:E11) -> 15238.914 | F12: =SUM(F6:F11) -> 681.08646 | G12: =SUM(G6:G11) -> 15920 | H12: =SUM(H6:H11) -> 15920 | I12: =SUM(I6:I11) -> 0 | J12: =IF(E12=0,0,F12/E12) -> 0.044693899 | K12: =IF(Segment_Inputs!C12=0,0,G12/Segment_Inputs!C12) -> 0.021446854 | L12: =IF(Segment_Inputs!J12=0,0,G12/Segment_Inputs!J12) -> 2.6098361
A14: Overlay control check (|overlay| <= 15% of modeled per segment) | F14: =IF(SUMPRODUCT(--(ABS(J6:J11)>0.15))=0,"OK","REVIEW") -> OK

Sheet README
A1: CECL Lifetime Expected Credit Loss Model (MDL-CR-007)
A2: Meridian Harbor Financial Corp. - model documentation sheet
A3: SYNTHETIC DOCUMENT FOR A PROOF OF CONCEPT. Meridian Harbor Financial Corp. is a fictional institution. All names, figures and events are invented and do not describe any real company.
A5: Model ID | B5: MDL-CR-007
A6: Model name | B6: CECL Lifetime Expected Credit Loss Model
A7: Risk tier | B7: Tier 1 (High)
A8: Model owner | B8: Consumer & Wholesale Credit Risk - Allowance Methodology
A9: Independent validator | B9: Model Risk Governance & Review (MRGR)
A10: Last validation | B10: 2025-11-04
A11: Next validation due | B11: 2026-11-30
A12: Purpose | B12: Estimates the allowance for credit losses under ASC 326 (CECL) using probability-weighted macroeconomic scenarios and PD x LGD x EAD.
A13: Upstream data feeds (APIs) | B13: API-10 Credit Risk Scoring API; API-11 Loan Servicing API; API-14 Macroeconomic Scenario API
A14: Downstream disclosures | B14: Annual Report - Allowance for Credit Losses (Note 6); Q2 2026 Earnings Supplement - Credit Trends
A15: Units | B15: USD millions unless stated otherwise; rates stored as decimals
A16: As-of date | B16: See Assumptions sheet
A18: Sheets
A19: Scenarios | B19: Probability-weighted macroeconomic scenarios (Upside / Baseline / Downside).
A20: Segment_Inputs | B20: Exposure at default, remaining life, PD and LGD parameters and macro sensitivities.
A21: ECL_Calc | B21: Scenario-conditional lifetime expected credit loss by segment.
A22: Allowance_Summary | B22: Probability-weighted allowance, qualitative overlay, reconciliation to the reported allowance and coverage metrics.
A23: Sensitivity | B23: Allowance under 100% weight on each single scenario.
A25: How the model works
A26: 1. | B26: Scenario PD = base annual PD x (1 + elasticity x (scenario peak unemployment - baseline unemployment) x 100), floored at 0.
A27: 2. | B27: Lifetime PD = 1 - (1 - scenario PD) ^ remaining life (years).
A28: 3. | B28: Scenario LGD = base LGD x (1 - LGD sensitivity x collateral price change), capped at 100%. Mortgages use the house price index (HPI); CRE uses the commercial property price index.
A29: 4. | B29: Scenario ECL = EAD x lifetime PD x scenario LGD. Modeled allowance = sum of scenario weight x ECL.
A30: 5. | B30: Total allowance = modeled allowance + qualitative overlay approved by the Allowance Committee.
A32: Key inputs
A33: 1. | B33: Loan balances (EAD) and remaining life from API-11 Loan Servicing API.
A34: 2. | B34: PD and LGD parameters from API-10 Credit Risk Scoring API (pool-level, refreshed quarterly).
A35: 3. | B35: Scenario paths and weights from API-14 Macroeconomic Scenario API (approved by the Scenario Committee).
A37: Key outputs
A38: 1. | B38: Allowance for loan losses by portfolio segment and in total.
A39: 2. | B39: Allowance coverage ratio (allowance / loans) and coverage of annual net charge-offs.
A40: 3. | B40: Sensitivity of the allowance to a 100% Downside weighting.
A42: Limits, controls and known limitations
A43: 1. | B43: Simplified pool-level approach for demonstration; production model uses loan-level cash flows.
A44: 2. | B44: Unfunded commitments (off-balance-sheet allowance) are excluded.
A45: 3. | B45: Qualitative overlays must be documented and fall within +/-15% of the modeled allowance per segment.
A46: 4. | B46: Scenario weights must sum to 100% (check cell on Scenarios sheet).
...

Sheet Scenarios
A1: Macroeconomic Scenarios
A2: Source: API-14 Macroeconomic Scenario API, scenario set MSC-2025Q4
A3: SYNTHETIC DOCUMENT FOR A PROOF OF CONCEPT. Meridian Harbor Financial Corp. is a fictional institution. All names, figures and events are invented and do not describe any real company.
A5: Scenario | B5: Weight | C5: Peak unemployment | D5: Real GDP growth 2026 | E5: House price index chg | F5: CRE price index chg
A6: Upside | B6: 0.2 | C6: 0.038 | D6: 0.026 | E6: 0.045 | F6: 0.03
A7: Baseline | B7: 0.5 | C7: 0.044 | D7: 0.017 | E7: 0.022 | F7: -0.01
A8: Downside | B8: 0.3 | C8: 0.068 | D8: -0.012 | E8: -0.085 | F8: -0.14
A9: Weight check | B9: =SUM(B6:B8) -> 1 | C9: =IF(ABS(B9-1)<0.0001,"OK","WEIGHTS MUST SUM TO 100%") -> OK
A11: Baseline unemployment (anchor) | B11: =C7 -> 0.044

Sheet Segment_Inputs
A1: Portfolio Segment Inputs
A2: Balances $mm at 2025-12-31
A3: SYNTHETIC DOCUMENT FOR A PROOF OF CONCEPT. Meridian Harbor Financial Corp. is a fictional institution. All names, figures and events are invented and do not describe any real company.
A5: Segment | B5: Owning LOB | C5: EAD / balance ($mm) | D5: Remaining life (yrs) | E5: Base annual PD | F5: Base LGD | G5: PD elasticity (per 1pp unemp.) | H5: LGD sensitivity to price | I5: Price driver | J5: FY2025 net charge-offs ($mm) | K5: Reported allowance ($mm)
A6: Credit Card | B6: CCB | C6: 138400 | D6: 1.7 | E6: 0.0374 | F6: 0.88 | G6: 0.165 | H6: 0 | I6: None | J6: 4620 | K6: 8640
A7: Residential Mortgage | B7: CCB | C7: 218600 | D7: 6.5 | E7: 0.0035 | F7: 0.14 | G7: 0.14 | H7: 1.8 | I7: HPI | J7: 40 | K7: 820
A8: Auto | B8: CCB | C8: 64900 | D8: 2.4 | E8: 0.0104 | F8: 0.42 | G8: 0.12 | H8: 0.4 | I8: None | J8: 410 | K8: 690
A9: Commercial Real Estate | B9: CIB | C9: 98200 | D9: 3.8 | E9: 0.0137 | F9: 0.38 | G9: 0.15 | H9: 1.6 | I9: CRE | J9: 380 | K9: 2470
A10: Commercial & Industrial | B10: CIB | C10: 172500 | D10: 2.3 | E10: 0.015 | F10: 0.41 | G10: 0.135 | H10: 0 | I10: None | J10: 560 | K10: 2760
A11: Other Consumer & Wholesale | B11: AWM/CCB | C11: 49700 | D11: 2 | E11: 0.0149 | F11: 0.33 | G11: 0.1 | H11: 0 | I11: None | J11: 90 | K11: 540
A12: Total | C12: =SUM(C6:C11) -> 742300 | J12: =SUM(J6:J11) -> 6100 | K12: =SUM(K6:K11) -> 15920

Sheet ECL_Calc
A1: Scenario-Conditional Lifetime ECL
A2: One block per scenario; rows = portfolio segments
A3: SYNTHETIC DOCUMENT FOR A PROOF OF CONCEPT. Meridian Harbor Financial Corp. is a fictional institution. All names, figures and events are invented and do not describe any real company.
A5: Scenario: Upside
A6: Segment | B6: Scenario PD (annual) | C6: Lifetime PD | D6: Collateral price chg | E6: Scenario LGD | F6: EAD ($mm) | G6: Lifetime ECL ($mm)
A7: =Segment_Inputs!A6 -> Credit Card | B7: =MAX(0,Segment_Inputs!E6*(1+Segment_Inputs!G6*(Scenarios!$C$6-Scenarios!$B$11)*100)) -> 0.0336974 | C7: =1-(1-B7)^Segment_Inputs!D6 -> 0.056607647 | D7: =IF(Segment_Inputs!I6="HPI",Scenarios!$E$6,IF(Segment_Inputs!I6="CRE",Scenarios!$F$6,0)) -> 0 | E7: =MIN(1,MAX(0,Segment_Inputs!F6*(1-Segment_Inputs!H6*D7))) -> 0.88 | F7: =Segment_Inputs!C6 -> 138400 | G7: =F7*C7*E7 -> 6894.3585
A8: =Segment_Inputs!A7 -> Residential Mortgage | B8: =MAX(0,Segment_Inputs!E7*(1+Segment_Inputs!G7*(Scenarios!$C$6-Scenarios!$B$11)*100)) -> 0.003206 | C8: =1-(1-B8)^Segment_Inputs!D7 -> 0.020656154 | D8: =IF(Segment_Inputs!I7="HPI",Scenarios!$E$6,IF(Segment_Inputs!I7="CRE",Scenarios!$F$6,0)) -> 0.045 | E8: =MIN(1,MAX(0,Segment_Inputs!F7*(1-Segment_Inputs!H7*D8))) -> 0.12866 | F8: =Segment_Inputs!C7 -> 218600 | G8: =F8*C8*E8 -> 580.9559
A9: =Segment_Inputs!A8 -> Auto | B9: =MAX(0,Segment_Inputs!E8*(1+Segment_Inputs!G8*(Scenarios!$C$6-Scenarios!$B$11)*100)) -> 0.0096512 | C9: =1-(1-B9)^Segment_Inputs!D8 -> 0.023006597 | D9: =IF(Segment_Inputs!I8="HPI",Scenarios!$E$6,IF(Segment_Inputs!I8="CRE",Scenarios!$F$6,0)) -> 0 | E9: =MIN(1,MAX(0,Segment_Inputs!F8*(1-Segment_Inputs!H8*D9))) -> 0.42 | F9: =Segment_Inputs!C8 -> 64900 | G9: =F9*C9*E9 -> 627.11382
A10: =Segment_Inputs!A9 -> Commercial Real Estate | B10: =MAX(0,Segment_Inputs!E9*(1+Segment_Inputs!G9*(Scenarios!$C$6-Scenarios!$B$11)*100)) -> 0.012467 | C10: =1-(1-B10)^Segment_Inputs!D9 -> 0.046553903 | D10: =IF(Segment_Inputs!I9="HPI",Scenarios!$E$6,IF(Segment_Inputs!I9="CRE",Scenarios!$F$6,0)) -> 0.03 | E10: =MIN(1,MAX(0,Segment_Inputs!F9*(1-Segment_Inputs!H9*D10))) -> 0.36176 | F10: =Segment_Inputs!C9 -> 98200 | G10: =F10*C10*E10 -> 1653.8196
A11: =Segment_Inputs!A10 -> Commercial & Industrial | B11: =MAX(0,Segment_Inputs!E10*(1+Segment_Inputs!G10*(Scenarios!$C$6-Scenarios!$B$11)*100)) -> 0.013785 | C11: =1-(1-B11)^Segment_Inputs!D10 -> 0.031421803 | D11: =IF(Segment_Inputs!I10="HPI",Scenarios!$E$6,IF(Segment_Inputs!I10="CRE",Scenarios!$F$6,0)) -> 0 | E11: =MIN(1,MAX(0,Segment_Inputs!F10*(1-Segment_Inputs!H10*D11))) -> 0.41 | F11: =Segment_Inputs!C10 -> 172500 | G11: =F11*C11*E11 -> 2222.307
A12: =Segment_Inputs!A11 -> Other Consumer & Wholesale | B12: =MAX(0,Segment_Inputs!E11*(1+Segment_Inputs!G11*(Scenarios!$C$6-Scenarios!$B$11)*100)) -> 0.014006 | C12: =1-(1-B12)^Segment_Inputs!D11 -> 0.027815832 | D12: =IF(Segment_Inputs!I11="HPI",Scenarios!$E$6,IF(Segment_Inputs!I11="CRE",Scenarios!$F$6,0)) -> 0 | E12: =MIN(1,MAX(0,Segment_Inputs!F11*(1-Segment_Inputs!H11*D12))) -> 0.33 | F12: =Segment_Inputs!C11 -> 49700 | G12: =F12*C12*E12 -> 456.20746
A13: Total - Upside | G13: =SUM(G7:G12) -> 12434.762
A15: Scenario: Baseline
A16: Segment | B16: Scenario PD (annual) | C16: Lifetime PD | D16: Collateral price chg | E16: Scenario LGD | F16: EAD ($mm) | G16: Lifetime ECL ($mm)
A17: =Segment_Inputs!A6 -> Credit Card | B17: =MAX(0,Segment_Inputs!E6*(1+Segment_Inputs!G6*(Scenarios!$C$7-Scenarios!$B$11)*100)) -> 0.0374 | C17: =1-(1-B17)^Segment_Inputs!D6 -> 0.062744587 | D17: =IF(Segment_Inputs!I6="HPI",Scenarios!$E$7,IF(Segment_Inputs!I6="CRE",Scenarios!$F$7,0)) -> 0 | E17: =MIN(1,MAX(0,Segment_Inputs!F6*(1-Segment_Inputs!H6*D17))) -> 0.88 | F17: =Segment_Inputs!C6 -> 138400 | G17: =F17*C17*E17 -> 7641.7887
A18: =Segment_Inputs!A7 -> Residential Mortgage | B18: =MAX(0,Segment_Inputs!E7*(1+Segment_Inputs!G7*(Scenarios!$C$7-Scenarios!$B$11)*100)) -> 0.0035 | C18: =1-(1-B18)^Segment_Inputs!D7 -> 0.022532177 | D18: =IF(Segment_Inputs!I7="HPI",Scenarios!$E$7,IF(Segment_Inputs!I7="CRE",Scenarios!$F$7,0)) -> 0.022 | E18: =MIN(1,MAX(0,Segment_Inputs!F7*(1-Segment_Inputs!H7*D18))) -> 0.134456 | F18: =Segment_Inputs!C7 -> 218600 | G18: =F18*C18*E18 -> 662.26759
A19: =Segment_Inputs!A8 -> Auto | B19: =MAX(0,Segment_Inputs!E8*(1+Segment_Inputs!G8*(Scenarios!$C$7-Scenarios!$B$11)*100)) -> 0.0104 | C19: =1-(1-B19)^Segment_Inputs!D8 -> 0.024778544 | D19: =IF(Segment_Inputs!I8="HPI",Scenarios!$E$7,IF(Segment_Inputs!I8="CRE",Scenarios!$F$7,0)) -> 0 | E19: =MIN(1,MAX(0,Segment_Inputs!F8*(1-Segment_Inputs!H8*D19))) -> 0.42 | F19: =Segment_Inputs!C8 -> 64900 | G19: =F19*C19*E19 -> 675.41354
A20: =Segment_Inputs!A9 -> Commercial Real Estate | B20: =MAX(0,Segment_Inputs!E9*(1+Segment_Inputs!G9*(Scenarios!$C$7-Scenarios!$B$11)*100)) -> 0.0137 | C20: =1-(1-B20)^Segment_Inputs!D9 -> 0.051069674 | D20: =IF(Segment_Inputs!I9="HPI",Scenarios!$E$7,IF(Segment_Inputs!I9="CRE",Scenarios!$F$7,0)) -> -0.01 | E20: =MIN(1,MAX(0,Segment_Inputs!F9*(1-Segment_Inputs!H9*D20))) -> 0.38608 | F20: =Segment_Inputs!C9 -> 98200 | G20: =F20*C20*E20 -> 1936.2074
A21: =Segment_Inputs!A10 -> Commercial & Industrial | B21: =MAX(0,Segment_Inputs!E10*(1+Segment_Inputs!G10*(Scenarios!$C$7-Scenarios!$B$11)*100)) -> 0.015 | C21: =1-(1-B21)^Segment_Inputs!D10 -> 0.034164131 | D21: =IF(Segment_Inputs!I10="HPI",Scenarios!$E$7,IF(Segment_Inputs!I10="CRE",Scenarios!$F$7,0)) -> 0 | E21: =MIN(1,MAX(0,Segment_Inputs!F10*(1-Segment_Inputs!H10*D21))) -> 0.41 | F21: =Segment_Inputs!C10 -> 172500 | G21: =F21*C21*E21 -> 2416.2582
A22: =Segment_Inputs!A11 -> Other Consumer & Wholesale | B22: =MAX(0,Segment_Inputs!E11*(1+Segment_Inputs!G11*(Scenarios!$C$7-Scenarios!$B$11)*100)) -> 0.0149 | C22: =1-(1-B22)^Segment_Inputs!D11 -> 0.02957799 | D22: =IF(Segment_Inputs!I11="HPI",Scenarios!$E$7,IF(Segment_Inputs!I11="CRE",Scenarios!$F$7,0)) -> 0 | E22: =MIN(1,MAX(0,Segment_Inputs!F11*(1-Segment_Inputs!H11*D22))) -> 0.33 | F22: =Segment_Inputs!C11 -> 49700 | G22: =F22*C22*E22 -> 485.10861
A23: Total - Baseline | G23: =SUM(G17:G22) -> 13817.044
A25: Scenario: Downside
A26: Segment | B26: Scenario PD (annual) | C26: Lifetime PD | D26: Collateral price chg | E26: Scenario LGD | F26: EAD ($mm) | G26: Lifetime ECL ($mm)
A27: =Segment_Inputs!A6 -> Credit Card | B27: =MAX(0,Segment_Inputs!E6*(1+Segment_Inputs!G6*(Scenarios!$C$8-Scenarios!$B$11)*100)) -> 0.0522104 | C27: =1-(1-B27)^Segment_Inputs!D6 -> 0.087127139 | D27: =IF(Segment_Inputs!I6="HPI",Scenarios!$E$8,IF(Segment_Inputs!I6="CRE",Scenarios!$F$8,0)) -> 0 | E27: =MIN(1,MAX(0,Segment_Inputs!F6*(1-Segment_Inputs!H6*D27))) -> 0.88 | F27: =Segment_Inputs!C6 -> 138400 | G27: =F27*C27*E27 -> 10611.388
A28: =Segment_Inputs!A7 -> Residential Mortgage | B28: =MAX(0,Segment_Inputs!E7*(1+Segment_Inputs!G7*(Scenarios!$C$8-Scenarios!$B$11)*100)) -> 0.004676 | C28: =1-(1-B28)^Segment_Inputs!D7 -> 0.030005894 | D28: =IF(Segment_Inputs!I7="HPI",Scenarios!$E$8,IF(Segment_Inputs!I7="CRE",Scenarios!$F$8,0)) -> -0.085 | E28: =MIN(1,MAX(0,Segment_Inputs!F7*(1-Segment_Inputs!H7*D28))) -> 0.16142 | F28: =Segment_Inputs!C7 -> 218600 | G28: =F28*C28*E28 -> 1058.8003
A29: =Segment_Inputs!A8 -> Auto | B29: =MAX(0,Segment_Inputs!E8*(1+Segment_Inputs!G8*(Scenarios!$C$8-Scenarios!$B$11)*100)) -> 0.0133952 | C29: =1-(1-B29)^Segment_Inputs!D8 -> 0.031847575 | D29: =IF(Segment_Inputs!I8="HPI",Scenarios!$E$8,IF(Segment_Inputs!I8="CRE",Scenarios!$F$8,0)) -> 0 | E29: =MIN(1,MAX(0,Segment_Inputs!F8*(1-Segment_Inputs!H8*D29))) -> 0.42 | F29: =Segment_Inputs!C8 -> 64900 | G29: =F29*C29*E29 -> 868.10119
A30: =Segment_Inputs!A9 -> Commercial Real Estate | B30: =MAX(0,Segment_Inputs!E9*(1+Segment_Inputs!G9*(Scenarios!$C$8-Scenarios!$B$11)*100)) -> 0.018632 | C30: =1-(1-B30)^Segment_Inputs!D9 -> 0.068975324 | D30: =IF(Segment_Inputs!I9="HPI",Scenarios!$E$8,IF(Segment_Inputs!I9="CRE",Scenarios!$F$8,0)) -> -0.14 | E30: =MIN(1,MAX(0,Segment_Inputs!F9*(1-Segment_Inputs!H9*D30))) -> 0.46512 | F30: =Segment_Inputs!C9 -> 98200 | G30: =F30*C30*E30 -> 3150.433
A31: =Segment_Inputs!A10 -> Commercial & Industrial | B31: =MAX(0,Segment_Inputs!E10*(1+Segment_Inputs!G10*(Scenarios!$C$8-Scenarios!$B$11)*100)) -> 0.01986 | C31: =1-(1-B31)^Segment_Inputs!D10 -> 0.045089518 | D31: =IF(Segment_Inputs!I10="HPI",Scenarios!$E$8,IF(Segment_Inputs!I10="CRE",Scenarios!$F$8,0)) -> 0 | E31: =MIN(1,MAX(0,Segment_Inputs!F10*(1-Segment_Inputs!H10*D31))) -> 0.41 | F31: =Segment_Inputs!C10 -> 172500 | G31: =F31*C31*E31 -> 3188.9562
A32: =Segment_Inputs!A11 -> Other Consumer & Wholesale | B32: =MAX(0,Segment_Inputs!E11*(1+Segment_Inputs!G11*(Scenarios!$C$8-Scenarios!$B$11)*100)) -> 0.018476 | C32: =1-(1-B32)^Segment_Inputs!D11 -> 0.036610637 | D32: =IF(Segment_Inputs!I11="HPI",Scenarios!$E$8,IF(Segment_Inputs!I11="CRE",Scenarios!$F$8,0)) -> 0 | E32: =MIN(1,MAX(0,Segment_Inputs!F11*(1-Segment_Inputs!H11*D32))) -> 0.33 | F32: =Segment_Inputs!C11 -> 49700 | G32: =F32*C32*E32 -> 600.45106
A33: Total - Downside | G33: =SUM(G27:G32) -> 19478.13

Sheet Sensitivity
A1: Allowance Sensitivity to Scenario Weighting
A2: Modeled allowance plus the same qualitative overlay
A3: SYNTHETIC DOCUMENT FOR A PROOF OF CONCEPT. Meridian Harbor Financial Corp. is a fictional institution. All names, figures and events are invented and do not describe any real company.
A5: Weighting | B5: Modeled ECL ($mm) | C5: Plus overlay ($mm) | D5: Change vs reported ($mm) | E5: Change (%)
A6: 100% Upside | B6: =Allowance_Summary!B12 -> 12434.762 | C6: =B6+Allowance_Summary!$F$12 -> 13115.849 | D6: =C6-Allowance_Summary!$H$12 -> -2804.1512 | E6: =IF(Allowance_Summary!$H$12=0,0,D6/Allowance_Summary!$H$12) -> -0.17614015
A7: 100% Baseline | B7: =Allowance_Summary!C12 -> 13817.044 | C7: =B7+Allowance_Summary!$F$12 -> 14498.13 | D7: =C7-Allowance_Summary!$H$12 -> -1421.8695 | E7: =IF(Allowance_Summary!$H$12=0,0,D7/Allowance_Summary!$H$12) -> -0.089313412
A8: 100% Downside | B8: =Allowance_Summary!D12 -> 19478.13 | C8: =B8+Allowance_Summary!$F$12 -> 20159.217 | D8: =C8-Allowance_Summary!$H$12 -> 4239.2167 | E8: =IF(Allowance_Summary!$H$12=0,0,D8/Allowance_Summary!$H$12) -> 0.26628245
A9: Probability-weighted (reported) | B9: =Allowance_Summary!E12 -> 15238.914 | C9: =B9+Allowance_Summary!$F$12 -> 15920 | D9: =C9-Allowance_Summary!$H$12 -> 0 | E9: =IF(Allowance_Summary!$H$12=0,0,D9/Allowance_Summary!$H$12) -> 0
