Workbook

Sheet README
A1: Net Interest Income Sensitivity Model (MDL-ALM-014)
A2: Meridian Harbor Financial Corp. - model documentation sheet
A3: SYNTHETIC DOCUMENT FOR A PROOF OF CONCEPT. Meridian Harbor Financial Corp. is a fictional institution. All names, figures and events are invented and do not describe any real company.
A5: Model ID | B5: MDL-ALM-014
A6: Model name | B6: Net Interest Income Sensitivity Model
A7: Risk tier | B7: Tier 1 (High)
A8: Model owner | B8: Corporate Treasury - Asset & Liability Management
A9: Independent validator | B9: Model Risk Governance & Review (MRGR)
A10: Last validation | B10: 2025-09-18
A11: Next validation due | B11: 2026-09-30
A12: Purpose | B12: Projects 12-month net interest income under parallel rate shocks and economic value of equity (EVE) sensitivity for IRRBB reporting.
A13: Upstream data feeds (APIs) | B13: API-12 Market Data API; API-15 Treasury Liquidity Positions API; API-11 Loan Servicing API
A14: Downstream disclosures | B14: Annual Report - Market Risk Management; Pillar 3 - Interest Rate Risk in the Banking Book
A15: Units | B15: USD millions unless stated otherwise; rates stored as decimals
A16: As-of date | B16: See Assumptions sheet
A18: Sheets
A19: Assumptions | B19: As-of date, policy rate, rate shock grid, repricing timing conventions, risk limits.
A20: Balance_Sheet | B20: Rate-sensitive assets and liabilities with balances, yields/costs, repricing profile, deposit betas and modified durations.
A21: NII_Projection | B21: Base-case 12-month NII and the change in NII for each parallel shock.
A22: EVE | B22: Economic value of equity sensitivity using a modified-duration approximation.
A23: Summary | B23: Results versus Board-approved IRRBB limits; feeds Annual Report and Pillar 3.
A25: How the model works
A26: 1. | B26: Base NII = sum over assets of balance x yield, minus sum over liabilities of balance x cost.
A27: 2. | B27: For each shock, every position reprices only for the fraction of the 12-month horizon remaining after its repricing date (bucket midpoint): 0-3m reprices at month 1.5, 3-12m at month 7.5.
A28: 3. | B28: Asset rates move one-for-one with the shock (asset beta in column L); liability rates move by shock x deposit beta.
A29: 4. | B29: Change in NII = asset repricing effect - liability repricing effect. Static balance sheet (no growth, no mix shift).
A30: 5. | B30: EVE change = -(asset value x modified duration - liability value x modified duration) x shock.
A32: Key inputs
A33: 1. | B33: Balances and yields from API-15 Treasury Liquidity Positions API (month-end snapshot).
A34: 2. | B34: Loan repricing profiles from API-11 Loan Servicing API.
A35: 3. | B35: Yield curve and policy rate from API-12 Market Data API.
A36: 4. | B36: Deposit betas from the Deposit Behaviour sub-model (annual calibration, MRGR approved).
A38: Key outputs
A39: 1. | B39: 12-month NII under +/-100 bp and +/-200 bp parallel shocks.
A40: 2. | B40: EVE sensitivity as a % of Tier 1 capital.
A41: 3. | B41: Limit utilisation flags used in ALCO reporting.
A43: Limits, controls and known limitations
A44: 1. | B44: Board limit: NII decline no greater than 7.0% of base NII in any parallel shock.
A45: 2. | B45: Board limit: EVE decline no greater than 15.0% of Tier 1 capital.
A46: 3. | B46: Limitations: parallel shocks only (no twists), static balance sheet, no rate floors on deposit costs below zero, betas held constant across shock sizes.
...

Sheet Summary
A1: IRRBB Summary vs Limits
A2: Feeds: Annual Report (Market Risk) and Pillar 3 (IRRBB)
A3: SYNTHETIC DOCUMENT FOR A PROOF OF CONCEPT. Meridian Harbor Financial Corp. is a fictional institution. All names, figures and events are invented and do not describe any real company.
A5: Scenario | B5: Shock (bps) | C5: Projected NII ($mm) | D5: Change in NII ($mm) | E5: Change in NII (%) | F5: NII limit status | G5: Change in EVE ($mm) | H5: EVE % of Tier 1 | I5: EVE limit status
A6: =Assumptions!A17 -> Down 200 | B6: =Assumptions!B17 -> -200 | C6: =NII_Projection!D24 -> 47220.022 | D6: =NII_Projection!D22 -> -3016.8875 | E6: =NII_Projection!D25 -> -0.060053206 | F6: =IF(E6<-Assumptions!$B$11,"BREACH","Within limit") -> Within limit | G6: =EVE!F22 -> 2737.4 | H6: =EVE!F24 -> 0.024745977 | I6: =IF(H6<-Assumptions!$B$12,"BREACH","Within limit") -> Within limit
A7: =Assumptions!A18 -> Down 100 | B7: =Assumptions!B18 -> -100 | C7: =NII_Projection!E24 -> 48728.466 | D7: =NII_Projection!E22 -> -1508.4437 | E7: =NII_Projection!E25 -> -0.030026603 | F7: =IF(E7<-Assumptions!$B$11,"BREACH","Within limit") -> Within limit | G7: =EVE!G22 -> 1368.7 | H7: =EVE!G24 -> 0.012372989 | I7: =IF(H7<-Assumptions!$B$12,"BREACH","Within limit") -> Within limit
A8: =Assumptions!A19 -> Base | B8: =Assumptions!B19 -> 0 | C8: =NII_Projection!F24 -> 50236.91 | D8: =NII_Projection!F22 -> 0 | E8: =NII_Projection!F25 -> 0 | F8: =IF(E8<-Assumptions!$B$11,"BREACH","Within limit") -> Within limit | G8: =EVE!H22 -> 0 | H8: =EVE!H24 -> 0 | I8: =IF(H8<-Assumptions!$B$12,"BREACH","Within limit") -> Within limit
A9: =Assumptions!A20 -> Up 100 | B9: =Assumptions!B20 -> 100 | C9: =NII_Projection!G24 -> 51745.354 | D9: =NII_Projection!G22 -> 1508.4437 | E9: =NII_Projection!G25 -> 0.030026603 | F9: =IF(E9<-Assumptions!$B$11,"BREACH","Within limit") -> Within limit | G9: =EVE!I22 -> -1368.7 | H9: =EVE!I24 -> -0.012372989 | I9: =IF(H9<-Assumptions!$B$12,"BREACH","Within limit") -> Within limit
A10: =Assumptions!A21 -> Up 200 | B10: =Assumptions!B21 -> 200 | C10: =NII_Projection!H24 -> 53253.798 | D10: =NII_Projection!H22 -> 3016.8875 | E10: =NII_Projection!H25 -> 0.060053206 | F10: =IF(E10<-Assumptions!$B$11,"BREACH","Within limit") -> Within limit | G10: =EVE!J22 -> -2737.4 | H10: =EVE!J24 -> -0.024745977 | I10: =IF(H10<-Assumptions!$B$12,"BREACH","Within limit") -> Within limit

Sheet Assumptions
A1: Assumptions
A2: All rates as decimals; shocks in basis points
A3: SYNTHETIC DOCUMENT FOR A PROOF OF CONCEPT. Meridian Harbor Financial Corp. is a fictional institution. All names, figures and events are invented and do not describe any real company.
A5: Assumption | B5: Value | C5: Source / note
A6: As-of date | B6: 2025-12-31 | C6: Month-end snapshot used for the FY2025 Annual Report.
A7: Policy rate (fed funds upper bound) | B7: 0.0375 | C7: Source: API-12 Market Data API, series POLICY.FEDFUNDS.UB
A8: Projection horizon (months) | B8: 12 | C8: Standard IRRBB earnings horizon.
A9: Repricing month - bucket 0-3m (midpoint) | B9: 1.5 | C9: Convention: midpoint of bucket.
A10: Repricing month - bucket 3-12m (midpoint) | B10: 7.5 | C10: Convention: midpoint of bucket.
A11: NII limit (max decline, % of base) | B11: 0.07 | C11: Board Risk Committee limit, approved 2025-03.
A12: EVE limit (max decline, % of Tier 1) | B12: 0.15 | C12: Board Risk Committee limit, approved 2025-03.
A13: Tier 1 capital ($mm) | B13: 110620 | C13: Source: API-16 Regulatory Reporting API, YE2025.
A16: Scenario | B16: Shock (bps)
A17: Down 200 | B17: -200
A18: Down 100 | B18: -100
A19: Base | B19: 0
A20: Up 100 | B20: 100
A21: Up 200 | B21: 200

Sheet Balance_Sheet
A1: Rate-Sensitive Balance Sheet
A2: Balances $mm at 2025-12-31; repricing shares sum to 100% per row
A3: SYNTHETIC DOCUMENT FOR A PROOF OF CONCEPT. Meridian Harbor Financial Corp. is a fictional institution. All names, figures and events are invented and do not describe any real company.
A5: Line | B5: Side | C5: Balance ($mm) | D5: Yield / cost | E5: Reprice 0-3m | F5: Reprice 3-12m | G5: Reprice 1-5y | H5: Reprice >5y | I5: Share check | J5: Annual interest ($mm) | K5: Mod. duration (yrs) | L5: Rate beta | M5: Feed
A6: Deposits with banks & fed funds sold | B6: Asset | C6: 246900 | D6: 0.0372 | E6: 1 | F6: 0 | G6: 0 | H6: 0 | I6: =IF(ABS(SUM(E6:H6)-1)<0.0001,"OK","CHECK") -> OK | J6: =C6*D6 -> 9184.68 | K6: 0.1 | L6: 1 | M6: API-15
A7: Investment securities (AFS + HTM) | B7: Asset | C7: 170900 | D7: 0.0386 | E7: 0.12 | F7: 0.1 | G7: 0.38 | H7: 0.4 | I7: =IF(ABS(SUM(E7:H7)-1)<0.0001,"OK","CHECK") -> OK | J7: =C7*D7 -> 6596.74 | K7: 4.6 | L7: 1 | M7: API-15
A8: Trading assets (interest-earning) | B8: Asset | C8: 98400 | D8: 0.041 | E8: 0.35 | F8: 0.25 | G8: 0.25 | H8: 0.15 | I8: =IF(ABS(SUM(E8:H8)-1)<0.0001,"OK","CHECK") -> OK | J8: =C8*D8 -> 4034.4 | K8: 2.1 | L8: 1 | M8: API-15
A9: Credit card loans | B9: Asset | C9: 138400 | D9: 0.165 | E9: 0.62 | F9: 0.08 | G9: 0.3 | H9: 0 | I9: =IF(ABS(SUM(E9:H9)-1)<0.0001,"OK","CHECK") -> OK | J9: =C9*D9 -> 22836 | K9: 0.9 | L9: 1 | M9: API-11
A10: Residential mortgage loans | B10: Asset | C10: 218600 | D10: 0.0428 | E10: 0.05 | F10: 0.07 | G10: 0.28 | H10: 0.6 | I10: =IF(ABS(SUM(E10:H10)-1)<0.0001,"OK","CHECK") -> OK | J10: =C10*D10 -> 9356.08 | K10: 5.8 | L10: 1 | M10: API-11
A11: Auto loans | B11: Asset | C11: 64900 | D11: 0.0655 | E11: 0.06 | F11: 0.24 | G11: 0.7 | H11: 0 | I11: =IF(ABS(SUM(E11:H11)-1)<0.0001,"OK","CHECK") -> OK | J11: =C11*D11 -> 4250.95 | K11: 1.7 | L11: 1 | M11: API-11
A12: Commercial real estate loans | B12: Asset | C12: 98200 | D12: 0.064 | E12: 0.55 | F12: 0.1 | G12: 0.3 | H12: 0.05 | I12: =IF(ABS(SUM(E12:H12)-1)<0.0001,"OK","CHECK") -> OK | J12: =C12*D12 -> 6284.8 | K12: 1.6 | L12: 1 | M12: API-11
A13: Commercial & industrial loans | B13: Asset | C13: 172500 | D13: 0.064 | E13: 0.78 | F13: 0.08 | G13: 0.12 | H13: 0.02 | I13: =IF(ABS(SUM(E13:H13)-1)<0.0001,"OK","CHECK") -> OK | J13: =C13*D13 -> 11040 | K13: 0.6 | L13: 1 | M13: API-11
A14: Other consumer & wholesale loans | B14: Asset | C14: 49700 | D14: 0.059 | E14: 0.5 | F14: 0.15 | G14: 0.3 | H14: 0.05 | I14: =IF(ABS(SUM(E14:H14)-1)<0.0001,"OK","CHECK") -> OK | J14: =C14*D14 -> 2932.3 | K14: 1.4 | L14: 1 | M14: API-11
A15: Consumer interest-bearing deposits | B15: Liability | C15: 402000 | D15: 0.0205 | E15: 0.7 | F15: 0.3 | G15: 0 | H15: 0 | I15: =IF(ABS(SUM(E15:H15)-1)<0.0001,"OK","CHECK") -> OK | J15: =C15*D15 -> 8241 | K15: 2.8 | L15: 0.45 | M15: API-15
A16: Wholesale interest-bearing deposits | B16: Liability | C16: 338400 | D16: 0.0315 | E16: 0.85 | F16: 0.15 | G16: 0 | H16: 0 | I16: =IF(ABS(SUM(E16:H16)-1)<0.0001,"OK","CHECK") -> OK | J16: =C16*D16 -> 10659.6 | K16: 0.6 | L16: 0.75 | M16: API-15
A17: Noninterest-bearing deposits | B17: Liability | C17: 272000 | D17: 0 | E17: 0 | F17: 0 | G17: 0.4 | H17: 0.6 | I17: =IF(ABS(SUM(E17:H17)-1)<0.0001,"OK","CHECK") -> OK | J17: =C17*D17 -> 0 | K17: 3.5 | L17: 0 | M17: API-15
... A19: Long-term debt | B19: Liability | C19: 86700 | D19: 0.0482 | E19: 0.3 | F19: 0.1 | G19: 0.35 | H19: 0.25 | I19: =IF(ABS(SUM(E19:H19)-1)<0.0001,"OK","CHECK") -> OK | J19: =C19*D19 -> 4178.94 | K19: 4.9 | L19: 1 | M19: API-15
A21: Total rate-sensitive assets | C21: =SUMIFS(C6:C19,B6:B19,"Asset") -> 1258500 | J21: =SUMIFS(J6:J19,B6:B19,"Asset") -> 76515.95
A22: Total rate-sensitive liabilities | C22: =SUMIFS(C6:C19,B6:B19,"Liability") -> 1180100 | J22: =SUMIFS(J6:J19,B6:B19,"Liability") -> 26279.04
A23: Base-case annual net interest income | J23: =J21-J22 -> 50236.91

Sheet NII_Projection
A1: 12-Month NII Projection by Parallel Shock
A2: Effect = balance x shock x beta x (share 0-3m x (H-1.5)/H + share 3-12m x (H-7.5)/H)
A3: SYNTHETIC DOCUMENT FOR A PROOF OF CONCEPT. Meridian Harbor Financial Corp. is a fictional institution. All names, figures and events are invented and do not describe any real company.
A5: Line | B5: Side | C5: Repricing factor | D5: Down 200 | E5: Down 100 | F5: Base | G5: Up 100 | H5: Up 200
A6: Shock (bps) | D6: =Assumptions!B17 -> -200 | E6: =Assumptions!B18 -> -100 | F6: =Assumptions!B19 -> 0 | G6: =Assumptions!B20 -> 100 | H6: =Assumptions!B21 -> 200
A7: =Balance_Sheet!A6 -> Deposits with banks & fed funds sold | B7: =Balance_Sheet!B6 -> Asset | C7: =Balance_Sheet!E6*(Assumptions!$B$8-Assumptions!$B$9)/Assumptions!$B$8+Balance_Sheet!F6*(Assumptions!$B$8-Assumptions!$B$10)/Assumptions!$B$8 -> 0.875 | D7: =IF(B7="Asset",1,-1)*Balance_Sheet!C6*Balance_Sheet!L6*$C7*D$6/10000 -> -4320.75 | E7: =IF(B7="Asset",1,-1)*Balance_Sheet!C6*Balance_Sheet!L6*$C7*E$6/10000 -> -2160.375 | F7: =IF(B7="Asset",1,-1)*Balance_Sheet!C6*Balance_Sheet!L6*$C7*F$6/10000 -> 0 | G7: =IF(B7="Asset",1,-1)*Balance_Sheet!C6*Balance_Sheet!L6*$C7*G$6/10000 -> 2160.375 | H7: =IF(B7="Asset",1,-1)*Balance_Sheet!C6*Balance_Sheet!L6*$C7*H$6/10000 -> 4320.75
A8: =Balance_Sheet!A7 -> Investment securities (AFS + HTM) | B8: =Balance_Sheet!B7 -> Asset | C8: =Balance_Sheet!E7*(Assumptions!$B$8-Assumptions!$B$9)/Assumptions!$B$8+Balance_Sheet!F7*(Assumptions!$B$8-Assumptions!$B$10)/Assumptions!$B$8 -> 0.1425 | D8: =IF(B8="Asset",1,-1)*Balance_Sheet!C7*Balance_Sheet!L7*$C8*D$6/10000 -> -487.065 | E8: =IF(B8="Asset",1,-1)*Balance_Sheet!C7*Balance_Sheet!L7*$C8*E$6/10000 -> -243.5325 | F8: =IF(B8="Asset",1,-1)*Balance_Sheet!C7*Balance_Sheet!L7*$C8*F$6/10000 -> 0 | G8: =IF(B8="Asset",1,-1)*Balance_Sheet!C7*Balance_Sheet!L7*$C8*G$6/10000 -> 243.5325 | H8: =IF(B8="Asset",1,-1)*Balance_Sheet!C7*Balance_Sheet!L7*$C8*H$6/10000 -> 487.065
A9: =Balance_Sheet!A8 -> Trading assets (interest-earning) | B9: =Balance_Sheet!B8 -> Asset | C9: =Balance_Sheet!E8*(Assumptions!$B$8-Assumptions!$B$9)/Assumptions!$B$8+Balance_Sheet!F8*(Assumptions!$B$8-Assumptions!$B$10)/Assumptions!$B$8 -> 0.4 | D9: =IF(B9="Asset",1,-1)*Balance_Sheet!C8*Balance_Sheet!L8*$C9*D$6/10000 -> -787.2 | E9: =IF(B9="Asset",1,-1)*Balance_Sheet!C8*Balance_Sheet!L8*$C9*E$6/10000 -> -393.6 | F9: =IF(B9="Asset",1,-1)*Balance_Sheet!C8*Balance_Sheet!L8*$C9*F$6/10000 -> 0 | G9: =IF(B9="Asset",1,-1)*Balance_Sheet!C8*Balance_Sheet!L8*$C9*G$6/10000 -> 393.6 | H9: =IF(B9="Asset",1,-1)*Balance_Sheet!C8*Balance_Sheet!L8*$C9*H$6/10000 -> 787.2
A10: =Balance_Sheet!A9 -> Credit card loans | B10: =Balance_Sheet!B9 -> Asset | C10: =Balance_Sheet!E9*(Assumptions!$B$8-Assumptions!$B$9)/Assumptions!$B$8+Balance_Sheet!F9*(Assumptions!$B$8-Assumptions!$B$10)/Assumptions!$B$8 -> 0.5725 | D10: =IF(B10="Asset",1,-1)*Balance_Sheet!C9*Balance_Sheet!L9*$C10*D$6/10000 -> -1584.68 | E10: =IF(B10="Asset",1,-1)*Balance_Sheet!C9*Balance_Sheet!L9*$C10*E$6/10000 -> -792.34 | F10: =IF(B10="Asset",1,-1)*Balance_Sheet!C9*Balance_Sheet!L9*$C10*F$6/10000 -> 0 | G10: =IF(B10="Asset",1,-1)*Balance_Sheet!C9*Balance_Sheet!L9*$C10*G$6/10000 -> 792.34 | H10: =IF(B10="Asset",1,-1)*Balance_Sheet!C9*Balance_Sheet!L9*$C10*H$6/10000 -> 1584.68
A11: =Balance_Sheet!A10 -> Residential mortgage loans | B11: =Balance_Sheet!B10 -> Asset | C11: =Balance_Sheet!E10*(Assumptions!$B$8-Assumptions!$B$9)/Assumptions!$B$8+Balance_Sheet!F10*(Assumptions!$B$8-Assumptions!$B$10)/Assumptions!$B$8 -> 0.07 | D11: =IF(B11="Asset",1,-1)*Balance_Sheet!C10*Balance_Sheet!L10*$C11*D$6/10000 -> -306.04 | E11: =IF(B11="Asset",1,-1)*Balance_Sheet!C10*Balance_Sheet!L10*$C11*E$6/10000 -> -153.02 | F11: =IF(B11="Asset",1,-1)*Balance_Sheet!C10*Balance_Sheet!L10*$C11*F$6/10000 -> 0 | G11: =IF(B11="Asset",1,-1)*Balance_Sheet!C10*Balance_Sheet!L10*$C11*G$6/10000 -> 153.02 | H11: =IF(B11="Asset",1,-1)*Balance_Sheet!C10*Balance_Sheet!L10*$C11*H$6/10000 -> 306.04
A12: =Balance_Sheet!A11 -> Auto loans | B12: =Balance_Sheet!B11 -> Asset | C12: =Balance_Sheet!E11*(Assumptions!$B$8-Assumptions!$B$9)/Assumptions!$B$8+Balance_Sheet!F11*(Assumptions!$B$8-Assumptions!$B$10)/Assumptions!$B$8 -> 0.1425 | D12: =IF(B12="Asset",1,-1)*Balance_Sheet!C11*Balance_Sheet!L11*$C12*D$6/10000 -> -184.965 | E12: =IF(B12="Asset",1,-1)*Balance_Sheet!C11*Balance_Sheet!L11*$C12*E$6/10000 -> -92.4825 | F12: =IF(B12="Asset",1,-1)*Balance_Sheet!C11*Balance_Sheet!L11*$C12*F$6/10000 -> 0 | G12: =IF(B12="Asset",1,-1)*Balance_Sheet!C11*Balance_Sheet!L11*$C12*G$6/10000 -> 92.4825 | H12: =IF(B12="Asset",1,-1)*Balance_Sheet!C11*Balance_Sheet!L11*$C12*H$6/10000 -> 184.965
A13: =Balance_Sheet!A12 -> Commercial real estate loans | B13: =Balance_Sheet!B12 -> Asset | C13: =Balance_Sheet!E12*(Assumptions!$B$8-Assumptions!$B$9)/Assumptions!$B$8+Balance_Sheet!F12*(Assumptions!$B$8-Assumptions!$B$10)/Assumptions!$B$8 -> 0.51875 | D13: =IF(B13="Asset",1,-1)*Balance_Sheet!C12*Balance_Sheet!L12*$C13*D$6/10000 -> -1018.825 | E13: =IF(B13="Asset",1,-1)*Balance_Sheet!C12*Balance_Sheet!L12*$C13*E$6/10000 -> -509.4125 | F13: =IF(B13="Asset",1,-1)*Balance_Sheet!C12*Balance_Sheet!L12*$C13*F$6/10000 -> 0 | G13: =IF(B13="Asset",1,-1)*Balance_Sheet!C12*Balance_Sheet!L12*$C13*G$6/10000 -> 509.4125 | H13: =IF(B13="Asset",1,-1)*Balance_Sheet!C12*Balance_Sheet!L12*$C13*H$6/10000 -> 1018.825
A14: =Balance_Sheet!A13 -> Commercial & industrial loans | B14: =Balance_Sheet!B13 -> Asset | C14: =Balance_Sheet!E13*(Assumptions!$B$8-Assumptions!$B$9)/Assumptions!$B$8+Balance_Sheet!F13*(Assumptions!$B$8-Assumptions!$B$10)/Assumptions!$B$8 -> 0.7125 | D14: =IF(B14="Asset",1,-1)*Balance_Sheet!C13*Balance_Sheet!L13*$C14*D$6/10000 -> -2458.125 | E14: =IF(B14="Asset",1,-1)*Balance_Sheet!C13*Balance_Sheet!L13*$C14*E$6/10000 -> -1229.0625 | F14: =IF(B14="Asset",1,-1)*Balance_Sheet!C13*Balance_Sheet!L13*$C14*F$6/10000 -> 0 | G14: =IF(B14="Asset",1,-1)*Balance_Sheet!C13*Balance_Sheet!L13*$C14*G$6/10000 -> 1229.0625 | H14: =IF(B14="Asset",1,-1)*Balance_Sheet!C13*Balance_Sheet!L13*$C14*H$6/10000 -> 2458.125
A15: =Balance_Sheet!A14 -> Other consumer & wholesale loans | B15: =Balance_Sheet!B14 -> Asset | C15: =Balance_Sheet!E14*(Assumptions!$B$8-Assumptions!$B$9)/Assumptions!$B$8+Balance_Sheet!F14*(Assumptions!$B$8-Assumptions!$B$10)/Assumptions!$B$8 -> 0.49375 | D15: =IF(B15="Asset",1,-1)*Balance_Sheet!C14*Balance_Sheet!L14*$C15*D$6/10000 -> -490.7875 | E15: =IF(B15="Asset",1,-1)*Balance_Sheet!C14*Balance_Sheet!L14*$C15*E$6/10000 -> -245.39375 | F15: =IF(B15="Asset",1,-1)*Balance_Sheet!C14*Balance_Sheet!L14*$C15*F$6/10000 -> 0 | G15: =IF(B15="Asset",1,-1)*Balance_Sheet!C14*Balance_Sheet!L14*$C15*G$6/10000 -> 245.39375 | H15: =IF(B15="Asset",1,-1)*Balance_Sheet!C14*Balance_Sheet!L14*$C15*H$6/10000 -> 490.7875
A16: =Balance_Sheet!A15 -> Consumer interest-bearing deposits | B16: =Balance_Sheet!B15 -> Liability | C16: =Balance_Sheet!E15*(Assumptions!$B$8-Assumptions!$B$9)/Assumptions!$B$8+Balance_Sheet!F15*(Assumptions!$B$8-Assumptions!$B$10)/Assumptions!$B$8 -> 0.725 | D16: =IF(B16="Asset",1,-1)*Balance_Sheet!C15*Balance_Sheet!L15*$C16*D$6/10000 -> 2623.05 | E16: =IF(B16="Asset",1,-1)*Balance_Sheet!C15*Balance_Sheet!L15*$C16*E$6/10000 -> 1311.525 | F16: =IF(B16="Asset",1,-1)*Balance_Sheet!C15*Balance_Sheet!L15*$C16*F$6/10000 -> 0 | G16: =IF(B16="Asset",1,-1)*Balance_Sheet!C15*Balance_Sheet!L15*$C16*G$6/10000 -> -1311.525 | H16: =IF(B16="Asset",1,-1)*Balance_Sheet!C15*Balance_Sheet!L15*$C16*H$6/10000 -> -2623.05
A17: =Balance_Sheet!A16 -> Wholesale interest-bearing deposits | B17: =Balance_Sheet!B16 -> Liability | C17: =Balance_Sheet!E16*(Assumptions!$B$8-Assumptions!$B$9)/Assumptions!$B$8+Balance_Sheet!F16*(Assumptions!$B$8-Assumptions!$B$10)/Assumptions!$B$8 -> 0.8 | D17: =IF(B17="Asset",1,-1)*Balance_Sheet!C16*Balance_Sheet!L16*$C17*D$6/10000 -> 4060.8 | E17: =IF(B17="Asset",1,-1)*Balance_Sheet!C16*Balance_Sheet!L16*$C17*E$6/10000 -> 2030.4 | F17: =IF(B17="Asset",1,-1)*Balance_Sheet!C16*Balance_Sheet!L16*$C17*F$6/10000 -> 0 | G17: =IF(B17="Asset",1,-1)*Balance_Sheet!C16*Balance_Sheet!L16*$C17*G$6/10000 -> -2030.4 | H17: =IF(B17="Asset",1,-1)*Balance_Sheet!C16*Balance_Sheet!L16*$C17*H$6/10000 -> -4060.8
A18: =Balance_Sheet!A17 -> Noninterest-bearing deposits | B18: =Balance_Sheet!B17 -> Liability | C18: =Balance_Sheet!E17*(Assumptions!$B$8-Assumptions!$B$9)/Assumptions!$B$8+Balance_Sheet!F17*(Assumptions!$B$8-Assumptions!$B$10)/Assumptions!$B$8 -> 0 | D18: =IF(B18="Asset",1,-1)*Balance_Sheet!C17*Balance_Sheet!L17*$C18*D$6/10000 -> 0 | E18: =IF(B18="Asset",1,-1)*Balance_Sheet!C17*Balance_Sheet!L17*$C18*E$6/10000 -> 0 | F18: =IF(B18="Asset",1,-1)*Balance_Sheet!C17*Balance_Sheet!L17*$C18*F$6/10000 -> 0 | G18: =IF(B18="Asset",1,-1)*Balance_Sheet!C17*Balance_Sheet!L17*$C18*G$6/10000 -> 0 | H18: =IF(B18="Asset",1,-1)*Balance_Sheet!C17*Balance_Sheet!L17*$C18*H$6/10000 -> 0
... A20: =Balance_Sheet!A19 -> Long-term debt | B20: =Balance_Sheet!B19 -> Liability | C20: =Balance_Sheet!E19*(Assumptions!$B$8-Assumptions!$B$9)/Assumptions!$B$8+Balance_Sheet!F19*(Assumptions!$B$8-Assumptions!$B$10)/Assumptions!$B$8 -> 0.3 | D20: =IF(B20="Asset",1,-1)*Balance_Sheet!C19*Balance_Sheet!L19*$C20*D$6/10000 -> 520.2 | E20: =IF(B20="Asset",1,-1)*Balance_Sheet!C19*Balance_Sheet!L19*$C20*E$6/10000 -> 260.1 | F20: =IF(B20="Asset",1,-1)*Balance_Sheet!C19*Balance_Sheet!L19*$C20*F$6/10000 -> 0 | G20: =IF(B20="Asset",1,-1)*Balance_Sheet!C19*Balance_Sheet!L19*$C20*G$6/10000 -> -260.1 | H20: =IF(B20="Asset",1,-1)*Balance_Sheet!C19*Balance_Sheet!L19*$C20*H$6/10000 -> -520.2
A22: Change in NII ($mm) | D22: =SUM(D7:D20) -> -3016.8875 | E22: =SUM(E7:E20) -> -1508.4437 | F22: =SUM(F7:F20) -> 0 | G22: =SUM(G7:G20) -> 1508.4437 | H22: =SUM(H7:H20) -> 3016.8875
A23: Base-case NII ($mm) | D23: =Balance_Sheet!$J$23 -> 50236.91 | E23: =Balance_Sheet!$J$23 -> 50236.91 | F23: =Balance_Sheet!$J$23 -> 50236.91 | G23: =Balance_Sheet!$J$23 -> 50236.91 | H23: =Balance_Sheet!$J$23 -> 50236.91
A24: Projected NII ($mm) | D24: =D23+D22 -> 47220.022 | E24: =E23+E22 -> 48728.466 | F24: =F23+F22 -> 50236.91 | G24: =G23+G22 -> 51745.354 | H24: =H23+H22 -> 53253.798
A25: Change in NII (%) | D25: =IF(D23=0,0,D22/D23) -> -0.060053206 | E25: =IF(E23=0,0,E22/E23) -> -0.030026603 | F25: =IF(F23=0,0,F22/F23) -> 0 | G25: =IF(G23=0,0,G22/G23) -> 0.030026603 | H25: =IF(H23=0,0,H22/H23) -> 0.060053206

Sheet EVE
A1: Economic Value of Equity Sensitivity
A2: dEVE ~= -(sum asset PV x duration - sum liability PV x duration) x shock
A3: SYNTHETIC DOCUMENT FOR A PROOF OF CONCEPT. Meridian Harbor Financial Corp. is a fictional institution. All names, figures and events are invented and do not describe any real company.
A5: Line | B5: Side | C5: Balance ($mm) | D5: Mod. duration | E5: Dollar duration ($mm per 100 bp) | F5: Down 200 | G5: Down 100 | H5: Base | I5: Up 100 | J5: Up 200
A6: Shock (bps) | F6: =Assumptions!B17 -> -200 | G6: =Assumptions!B18 -> -100 | H6: =Assumptions!B19 -> 0 | I6: =Assumptions!B20 -> 100 | J6: =Assumptions!B21 -> 200
A7: =Balance_Sheet!A6 -> Deposits with banks & fed funds sold | B7: =Balance_Sheet!B6 -> Asset | C7: =Balance_Sheet!C6 -> 246900 | D7: =Balance_Sheet!K6 -> 0.1 | E7: =IF(B7="Asset",1,-1)*C7*D7/100 -> 246.9 | F7: =-$E7*F$6/100 -> 493.8 | G7: =-$E7*G$6/100 -> 246.9 | H7: =-$E7*H$6/100 -> 0 | I7: =-$E7*I$6/100 -> -246.9 | J7: =-$E7*J$6/100 -> -493.8
A8: =Balance_Sheet!A7 -> Investment securities (AFS + HTM) | B8: =Balance_Sheet!B7 -> Asset | C8: =Balance_Sheet!C7 -> 170900 | D8: =Balance_Sheet!K7 -> 4.6 | E8: =IF(B8="Asset",1,-1)*C8*D8/100 -> 7861.4 | F8: =-$E8*F$6/100 -> 15722.8 | G8: =-$E8*G$6/100 -> 7861.4 | H8: =-$E8*H$6/100 -> 0 | I8: =-$E8*I$6/100 -> -7861.4 | J8: =-$E8*J$6/100 -> -15722.8
A9: =Balance_Sheet!A8 -> Trading assets (interest-earning) | B9: =Balance_Sheet!B8 -> Asset | C9: =Balance_Sheet!C8 -> 98400 | D9: =Balance_Sheet!K8 -> 2.1 | E9: =IF(B9="Asset",1,-1)*C9*D9/100 -> 2066.4 | F9: =-$E9*F$6/100 -> 4132.8 | G9: =-$E9*G$6/100 -> 2066.4 | H9: =-$E9*H$6/100 -> 0 | I9: =-$E9*I$6/100 -> -2066.4 | J9: =-$E9*J$6/100 -> -4132.8
A10: =Balance_Sheet!A9 -> Credit card loans | B10: =Balance_Sheet!B9 -> Asset | C10: =Balance_Sheet!C9 -> 138400 | D10: =Balance_Sheet!K9 -> 0.9 | E10: =IF(B10="Asset",1,-1)*C10*D10/100 -> 1245.6 | F10: =-$E10*F$6/100 -> 2491.2 | G10: =-$E10*G$6/100 -> 1245.6 | H10: =-$E10*H$6/100 -> 0 | I10: =-$E10*I$6/100 -> -1245.6 | J10: =-$E10*J$6/100 -> -2491.2
A11: =Balance_Sheet!A10 -> Residential mortgage loans | B11: =Balance_Sheet!B10 -> Asset | C11: =Balance_Sheet!C10 -> 218600 | D11: =Balance_Sheet!K10 -> 5.8 | E11: =IF(B11="Asset",1,-1)*C11*D11/100 -> 12678.8 | F11: =-$E11*F$6/100 -> 25357.6 | G11: =-$E11*G$6/100 -> 12678.8 | H11: =-$E11*H$6/100 -> 0 | I11: =-$E11*I$6/100 -> -12678.8 | J11: =-$E11*J$6/100 -> -25357.6
A12: =Balance_Sheet!A11 -> Auto loans | B12: =Balance_Sheet!B11 -> Asset | C12: =Balance_Sheet!C11 -> 64900 | D12: =Balance_Sheet!K11 -> 1.7 | E12: =IF(B12="Asset",1,-1)*C12*D12/100 -> 1103.3 | F12: =-$E12*F$6/100 -> 2206.6 | G12: =-$E12*G$6/100 -> 1103.3 | H12: =-$E12*H$6/100 -> 0 | I12: =-$E12*I$6/100 -> -1103.3 | J12: =-$E12*J$6/100 -> -2206.6
A13: =Balance_Sheet!A12 -> Commercial real estate loans | B13: =Balance_Sheet!B12 -> Asset | C13: =Balance_Sheet!C12 -> 98200 | D13: =Balance_Sheet!K12 -> 1.6 | E13: =IF(B13="Asset",1,-1)*C13*D13/100 -> 1571.2 | F13: =-$E13*F$6/100 -> 3142.4 | G13: =-$E13*G$6/100 -> 1571.2 | H13: =-$E13*H$6/100 -> 0 | I13: =-$E13*I$6/100 -> -1571.2 | J13: =-$E13*J$6/100 -> -3142.4
A14: =Balance_Sheet!A13 -> Commercial & industrial loans | B14: =Balance_Sheet!B13 -> Asset | C14: =Balance_Sheet!C13 -> 172500 | D14: =Balance_Sheet!K13 -> 0.6 | E14: =IF(B14="Asset",1,-1)*C14*D14/100 -> 1035 | F14: =-$E14*F$6/100 -> 2070 | G14: =-$E14*G$6/100 -> 1035 | H14: =-$E14*H$6/100 -> 0 | I14: =-$E14*I$6/100 -> -1035 | J14: =-$E14*J$6/100 -> -2070
A15: =Balance_Sheet!A14 -> Other consumer & wholesale loans | B15: =Balance_Sheet!B14 -> Asset | C15: =Balance_Sheet!C14 -> 49700 | D15: =Balance_Sheet!K14 -> 1.4 | E15: =IF(B15="Asset",1,-1)*C15*D15/100 -> 695.8 | F15: =-$E15*F$6/100 -> 1391.6 | G15: =-$E15*G$6/100 -> 695.8 | H15: =-$E15*H$6/100 -> 0 | I15: =-$E15*I$6/100 -> -695.8 | J15: =-$E15*J$6/100 -> -1391.6
A16: =Balance_Sheet!A15 -> Consumer interest-bearing deposits | B16: =Balance_Sheet!B15 -> Liability | C16: =Balance_Sheet!C15 -> 402000 | D16: =Balance_Sheet!K15 -> 2.8 | E16: =IF(B16="Asset",1,-1)*C16*D16/100 -> -11256 | F16: =-$E16*F$6/100 -> -22512 | G16: =-$E16*G$6/100 -> -11256 | H16: =-$E16*H$6/100 -> 0 | I16: =-$E16*I$6/100 -> 11256 | J16: =-$E16*J$6/100 -> 22512
A17: =Balance_Sheet!A16 -> Wholesale interest-bearing deposits | B17: =Balance_Sheet!B16 -> Liability | C17: =Balance_Sheet!C16 -> 338400 | D17: =Balance_Sheet!K16 -> 0.6 | E17: =IF(B17="Asset",1,-1)*C17*D17/100 -> -2030.4 | F17: =-$E17*F$6/100 -> -4060.8 | G17: =-$E17*G$6/100 -> -2030.4 | H17: =-$E17*H$6/100 -> 0 | I17: =-$E17*I$6/100 -> 2030.4 | J17: =-$E17*J$6/100 -> 4060.8
A18: =Balance_Sheet!A17 -> Noninterest-bearing deposits | B18: =Balance_Sheet!B17 -> Liability | C18: =Balance_Sheet!C17 -> 272000 | D18: =Balance_Sheet!K17 -> 3.5 | E18: =IF(B18="Asset",1,-1)*C18*D18/100 -> -9520 | F18: =-$E18*F$6/100 -> -19040 | G18: =-$E18*G$6/100 -> -9520 | H18: =-$E18*H$6/100 -> 0 | I18: =-$E18*I$6/100 -> 9520 | J18: =-$E18*J$6/100 -> 19040
... A20: =Balance_Sheet!A19 -> Long-term debt | B20: =Balance_Sheet!B19 -> Liability | C20: =Balance_Sheet!C19 -> 86700 | D20: =Balance_Sheet!K19 -> 4.9 | E20: =IF(B20="Asset",1,-1)*C20*D20/100 -> -4248.3 | F20: =-$E20*F$6/100 -> -8496.6 | G20: =-$E20*G$6/100 -> -4248.3 | H20: =-$E20*H$6/100 -> 0 | I20: =-$E20*I$6/100 -> 4248.3 | J20: =-$E20*J$6/100 -> 8496.6
A22: Change in EVE ($mm) | F22: =SUM(F7:F20) -> 2737.4 | G22: =SUM(G7:G20) -> 1368.7 | H22: =SUM(H7:H20) -> 0 | I22: =SUM(I7:I20) -> -1368.7 | J22: =SUM(J7:J20) -> -2737.4
A23: Tier 1 capital ($mm) | F23: =Assumptions!$B$13 -> 110620 | G23: =Assumptions!$B$13 -> 110620 | H23: =Assumptions!$B$13 -> 110620 | I23: =Assumptions!$B$13 -> 110620 | J23: =Assumptions!$B$13 -> 110620
A24: Change in EVE (% of Tier 1) | F24: =IF(F23=0,0,F22/F23) -> 0.024745977 | G24: =IF(G23=0,0,G22/G23) -> 0.012372989 | H24: =IF(H23=0,0,H22/H23) -> 0 | I24: =IF(I23=0,0,I22/I23) -> -0.012372989 | J24: =IF(J23=0,0,J22/J23) -> -0.024745977
